<?xml version='1.0'?>
<sdf version='1.4'>
    <model name='robot_model' canonical_link='chassis'>
        <!-- <pose relative_to='world'>0 0 0 0 0 0</pose> -->

        <frame name="lidar_frame" attached_to='chassis'>
            <pose>0.8 0 0.5 0 0 0</pose>
        </frame>
        
        <link name='chassis'>
            <pose relative_to='__model__'>0.5 0 0.4 0 0 0</pose>
            <inertial> <!--inertial properties of the link mass, inertia matrix-->
                <mass>1.14395</mass>
                <inertia>
                    <ixx>0.095329</ixx>
                    <ixy>0</ixy>
                    <ixz>0</ixz>
                    <iyy>0.381317</iyy>
                    <iyz>0</iyz>
                    <izz>0.476646</izz>
                </inertia>
            </inertial>

            <visual name='visual'>
                <geometry>
                    <box>
                        <size>2.0 1.0 0.5</size>
                    </box>
                </geometry>
                <!--let's add color to our link-->
                <material>
                    <ambient>0.0 0.0 1.0 1</ambient>
                    <diffuse>0.0 0.0 1.0 1</diffuse>
                    <specular>0.0 0.0 1.0 1</specular>
                </material>
            </visual>

            <collision name='collision'>
                <geometry>
                    <box>
                        <size>2.0 1.0 0.5</size>
                    </box>
                </geometry>
            </collision>

            <!-- Sensors -->

            <sensor name="imu_sensor" type="imu">
                <always_on>1</always_on>
                <update_rate>1</update_rate>
                <visualize>true</visualize>
                <!-- <topic>imu</topic> -->
            </sensor>

            <sensor name='gpu_lidar' type='gpu_lidar'>"
                <pose relative_to='lidar_frame'>0 0 0 0 0 0</pose>
                <!-- <topic>lidar</topic> -->
                <update_rate>10</update_rate>
                <ray>
                    <scan>
                        <horizontal>
                            <samples>640</samples>
                            <resolution>1</resolution>
                            <min_angle>-0.74351026135</min_angle>
                            <max_angle>0.74351026135</max_angle>
                        </horizontal>
                        <vertical>
                            <samples>480</samples>
                            <resolution>1</resolution>
                            <min_angle>-0.50614548307</min_angle>
                            <max_angle>0.50614548307</max_angle>
                        </vertical>
                    </scan>
                <range>
                    <min>0.08</min>
                    <max>10.0</max>
                    <resolution>0.01</resolution>
                </range>
                </ray>
                <always_on>1</always_on>
                <visualize>true</visualize>
            </sensor>
        </link>

        <!-- <link name='rgb_camera'>
            <pose relative_to='chassis'>1 0 0.3 0 0 0</pose>
            <visual name="visual">
                <geometry>
                    <box>
                        <size>0.1 0.3 0.2</size>
                    </box>
                </geometry>
                <material>
                    <ambient>0 0 1 1</ambient>
                </material>
            </visual>
            <sensor name='rgb_camera_sensor' type='camera'>
                <update_rate>30</update_rate>
                <camera>
                    <horizontal_fov>1.047</horizontal_fov>
                    <image>
                        <width>640</width>
                        <height>480</height>
                        <format>R8G8B8</format>
                    </image>
                    <clip>
                        <near>0.1</near>
                        <far>100.0</far>
                    </clip>
                </camera>
                <always_on>1</always_on>
                <visualize>true</visualize>
                <topic>rgb_camera</topic>
            </sensor>
        </link> -->

        <link name='left_wheel'>
            <pose relative_to="chassis">-0.5 0.6 0 -1.5707 0 0</pose>
            <inertial>
                <mass>1</mass>
                <inertia>
                    <ixx>0.043333</ixx>
                    <ixy>0</ixy>
                    <ixz>0</ixz>
                    <iyy>0.043333</iyy>
                    <iyz>0</iyz>
                    <izz>0.08</izz>
                </inertia>
            </inertial>
            <visual name='visual'>
                <geometry>
                    <cylinder>
                        <radius>0.4</radius>
                        <length>0.2</length>
                    </cylinder>
                </geometry>
                <material>
                    <ambient>1.0 0.0 0.0 1</ambient>
                    <diffuse>1.0 0.0 0.0 1</diffuse>
                    <specular>1.0 0.0 0.0 1</specular>
                </material>
            </visual>
            <collision name='collision'>
                <geometry>
                    <cylinder>
                        <radius>0.4</radius>
                        <length>0.2</length>
                    </cylinder>
                </geometry>
            </collision>
        </link>

        <link name='right_wheel'>
            <pose relative_to="chassis">-0.5 -0.6 0 -1.5707 0 0</pose> <!--angles are in radian-->
            <inertial>
                <mass>1</mass>
                <inertia>
                    <ixx>0.043333</ixx>
                    <ixy>0</ixy>
                    <ixz>0</ixz>
                    <iyy>0.043333</iyy>
                    <iyz>0</iyz>
                    <izz>0.08</izz>
                </inertia>
            </inertial>
            <visual name='visual'>
                <geometry>
                    <cylinder>
                        <radius>0.4</radius>
                        <length>0.2</length>
                    </cylinder>
                </geometry>
                <material>
                    <ambient>1.0 0.0 0.0 1</ambient>
                    <diffuse>1.0 0.0 0.0 1</diffuse>
                    <specular>1.0 0.0 0.0 1</specular>
                </material>
            </visual>
            <collision name='collision'>
                <geometry>
                    <cylinder>
                        <radius>0.4</radius>
                        <length>0.2</length>
                    </cylinder>
                </geometry>
            </collision>
        </link>

        <frame name="caster_frame" attached_to='chassis'>
            <pose>0.8 0 -0.2 0 0 0</pose>
        </frame>

        <!-- A caster wheel to prevent the robot from tipping over -->
        <link name='caster'>
            <pose relative_to='caster_frame'/>
            <inertial>
                <mass>1</mass>
                <inertia>
                    <ixx>0.016</ixx>
                    <ixy>0</ixy>
                    <ixz>0</ixz>
                    <iyy>0.016</iyy>
                    <iyz>0</iyz>
                    <izz>0.016</izz>
                </inertia>
            </inertial>
            <visual name='visual'>
                <geometry>
                    <sphere>
                        <radius>0.2</radius>
                    </sphere>
                </geometry>
                <material>
                    <ambient>0.0 1 0.0 1</ambient>
                    <diffuse>0.0 1 0.0 1</diffuse>
                    <specular>0.0 1 0.0 1</specular>
                </material>
            </visual>
            <collision name='collision'>
                <geometry>
                    <sphere>
                        <radius>0.2</radius>
                    </sphere>
                </geometry>
            </collision>
        </link>

        <!-- Joints -->

        <joint name='left_wheel_joint' type='revolute'>
            <pose relative_to='left_wheel'/>
            <parent>chassis</parent>
            <child>left_wheel</child>
            <axis>
                <xyz expressed_in='__model__'>0 1 0</xyz> <!--can be defined as any frame or even arbitrary frames-->
                <limit>
                    <lower>-1.79769e+308</lower>    <!--negative infinity-->
                    <upper>1.79769e+308</upper>     <!--positive infinity-->
                </limit>
            </axis>
        </joint>

        <joint name='right_wheel_joint' type='revolute'>
            <pose relative_to='right_wheel'/>
            <parent>chassis</parent>
            <child>right_wheel</child>
            <axis>
                <xyz expressed_in='__model__'>0 1 0</xyz>
                <limit>
                    <lower>-1.79769e+308</lower>    <!--negative infinity-->
                    <upper>1.79769e+308</upper>     <!--positive infinity-->
                </limit>
            </axis>
        </joint>

        <joint name='caster_wheel' type='ball'>
            <parent>chassis</parent>
            <child>caster</child>
        </joint>

        <!-- <joint name='camera_joint' type='fixed'>
            <parent>chassis</parent>
            <child>rgb_camera</child>
        </joint> -->

        <!-- Diff Drive Plugin -->
        <plugin filename="gz-sim-diff-drive-system" name="gz::sim::systems::DiffDrive">
            <left_joint>left_wheel_joint</left_joint>
            <right_joint>right_wheel_joint</right_joint>
            <wheel_separation>1.2</wheel_separation>
            <wheel_radius>0.4</wheel_radius>

            <odom_publish_frequency>1</odom_publish_frequency>
            <!-- <topic>cmd_vel</topic> -->
            <!-- <odom_topic>odom</odom_topic> -->
            <!-- <tf_topic>tf</tf_topic> -->
            <frame_id>odom</frame_id>
            <child_frame_id>chassis</child_frame_id>
        </plugin>

        <plugin filename="gz-sim-joint-state-publisher-system" name="gz::sim::systems::JointStatePublisher">
            <topic>joint_states</topic>
        </plugin>
    </model>
</sdf>